Workbook

Sheet Resultado Real
A1: Hora-Data | B1: Data | C1: Horário | D1: Mandante | E1: Placar Mandante | F1: x | G1: Placar Visitante | H1: Visitante | K1: Ranking | L1: Participante | M1: Pontuação
A2: 11.06. 16:00 | B2: 11/06/2026 | C2: 16:00 | D2: México | F2: x | H2: África do Sul | K2: 1 | L2: {=_xlfn.SORTBY(Ranking!A2:B80,Ranking!B2:B80,-1)} -> Alessandro Pignata | M2: 0
A3: 11.06. 23:00 | B3: 11/06/2026 | C3: 23:00 | D3: Coreia do Sul | F3: x | H3: Republica Tcheca | K3: 2 | L3: Benjamin Cavallari | M3: 0
A4: 12.06. 16:00 | B4: 12/06/2026 | C4: 16:00 | D4: Canadá | F4: x | H4: Bósnia e Herzegovina | K4: 3 | L4: Bruno Firmino | M4: 0
A5: 12.06. 22:00 | B5: 12/06/2026 | C5: 22:00 | D5: EUA | F5: x | H5: Paraguai | K5: 4 | L5: Claudiomar Belao | M5: 0
A6: 13.06. 16:00 | B6: 13/06/2026 | C6: 16:00 | D6: Catar | F6: x | H6: Suíça | K6: 5 | L6: Dirceu Duarte | M6: 0
A7: 13.06. 19:00 | B7: 13/06/2026 | C7: 19:00 | D7: Brasil | F7: x | H7: Marrocos | K7: 6 | L7: Eduardo Colli | M7: 0
A8: 13.06. 22:00 | B8: 13/06/2026 | C8: 22:00 | D8: Haiti | F8: x | H8: Escócia | K8: 7 | L8: Felipe Gambini | M8: 0
A9: 14.06. 01:00 | B9: 14/06/2026 | C9: 01:00 | D9: Austrália | F9: x | H9: Turquia | K9: 8 | L9: Gustavo Cavallari | M9: 0
A10: 14.06. 14:00 | B10: 14/06/2026 | C10: 14:00 | D10: Alemanha | F10: x | H10: Curaçau | K10: 9 | L10: Higor Frez | M10: 0
A11: 14.06. 17:00 | B11: 14/06/2026 | C11: 17:00 | D11: Países Baixos | F11: x | H11: Japão | K11: 10 | L11: Humberto Mozer | M11: 0
A12: 14.06. 20:00 | B12: 14/06/2026 | C12: 20:00 | D12: Costa do Marfim | F12: x | H12: Equador | K12: 11 | L12: Julio Lima | M12: 0
A13: 14.06. 23:00 | B13: 14/06/2026 | C13: 23:00 | D13: Suécia | F13: x | H13: Tunísia | K13: 12 | L13: Lincoln Macena | M13: 0
A14: 15.06. 13:00 | B14: 15/06/2026 | C14: 13:00 | D14: Espanha | F14: x | H14: Cabo Verde | K14: 13 | L14: Luan Altimari | M14: 0
... A73: 27.06. 23:00 | B73: 27/06/2026 | C73: 23:00 | D73: Jordânia | F73: x | H73: Argentina | K73: 72 | L73: Emerson Batta | M73: 0
K74: 73 | L74: Caique Pereira | M74: 0
L75: 0 | M75: 0
L76: 0 | M76: 0
L77: 0 | M77: 0
L78: 0 | M78: 0
L79: 0 | M79: 0
L80: 0 | M80: 0

Sheet Ranking
A1: Participante | B1: Pontuação Atual
A2: Alessandro Pignata | B2: ='Alessandro Pignata'!K2 -> 0
A3: Benjamin Cavallari | B3: ='Benjamin Cavallari'!K2 -> 0
A4: Bruno Firmino | B4: ='Bruno Firmino'!K2 -> 0
A5: Claudiomar Belao | B5: ='Claudiomar Belao'!K2 -> 0
A6: Dirceu Duarte | B6: ='Dirceu Duarte'!K2 -> 0
A7: Eduardo Colli | B7: ='Eduardo Colli'!K2 -> 0
A8: Felipe Gambini | B8: ='Felipe Gambini'!K2 -> 0
A9: Gustavo Cavallari | B9: ='Gustavo Cavallari'!K2 -> 0
A10: Higor Frez | B10: ='Higor Frez'!K2 -> 0
A11: Humberto Mozer | B11: ='Humberto Mozer'!K2 -> 0
A12: Julio Lima | B12: ='Julio Lima'!K2 -> 0
A13: Lincoln Macena | B13: ='Lincoln Macena'!K2 -> 0
A14: Luan Altimari | B14: ='Luan Altimari'!K2 -> 0
A15: Luis Gustavo Pereira | B15: ='Luis Gustavo Pereira'!K2 -> 0
A16: Marcão Penap | B16: ='Marcão Penap'!K2 -> 0
A17: Rafael Cavallari | B17: ='Rafael Cavallari'!K2 -> 0
A18: Ricardo Alonso | B18: ='Ricardo Alonso'!K2 -> 0
A19: Rogério Penap | B19: ='Rogério Penap'!K2 -> 0
A20: Théo Cavallari | B20: ='Théo Cavallari'!K2 -> 0
A21: Wesley Alonso | B21: ='Wesley Alonso'!K2 -> 0
A22: Agnaldo | B22: =Agnaldo!K2 -> 0
A23: Carlos Malta | B23: ='Carlos Malta'!K2 -> 0
A24: Carlos (Grilo) | B24: ='Carlos (Grilo)'!K2 -> 0
A25: Carlos Rocha (Carlinho) | B25: ='Carlos Rocha (Carlinho)'!K2 -> 0
A26: Daniel Batista | B26: ='Daniel Batista'!K2 -> 0
A27: Daniel Marroni | B27: ='Daniel Marroni'!K2 -> 0
A28: Dercio Batista | B28: ='Dercio Batista'!K2 -> 0
A29: Dionisio Junior | B29: ='Dionisio Junior'!K2 -> 0
A30: Dirce Batista | B30: ='Dirce Batista'!K2 -> 0
A31: Eneias Aguiar | B31: ='Eneias Aguiar'!K2 -> 0
A32: Gabriel Cavallari | B32: ='Gabriel Cavallari'!K2 -> 0
A33: Gabriel Rubinho | B33: ='Gabriel Rubinho'!K2 -> 0
A34: Iann Altimari | B34: ='Iann Altimari'!K2 -> 0
A35: Jean Rocha | B35: ='Jean Rocha'!K2 -> 0
A36: Jonatas Andrade | B36: ='Jonatas Andrade'!K2 -> 0
A37: Junior (Goiaba) | B37: ='Junior (Goiaba)'!K2 -> 0
A38: Kayky Rocha | B38: ='Kayky Rocha'!K2 -> 0
A39: Lucas Altimari | B39: ='Lucas Altimari'!K2 -> 0
A40: Luis Alfredo | B40: ='Luis Alfredo'!K2 -> 0
...

Sheet Layout Compartilhável
A1: Hora-Data | B1: Data | C1: Horário | D1: Mandante | E1: Placar Mandante | F1: x | G1: Placar Visitante | H1: Visitante
A2: 11.06. 16:00 | B2: 11/06/2026 | C2: 16:00 | D2: México | F2: x | H2: África do Sul | J2: Nome Participante (Preencher)
A3: 11.06. 23:00 | B3: 11/06/2026 | C3: 23:00 | D3: Coreia do Sul | F3: x | H3: Republica Tcheca
A4: 12.06. 16:00 | B4: 12/06/2026 | C4: 16:00 | D4: Canadá | F4: x | H4: Bósnia e Herzegovina
A5: 12.06. 22:00 | B5: 12/06/2026 | C5: 22:00 | D5: EUA | F5: x | H5: Paraguai | J5: PIX BOLÃO (R$ 30,00)
A6: 13.06. 16:00 | B6: 13/06/2026 | C6: 16:00 | D6: Catar | F6: x | H6: Suíça | J6: 00-000-000
A7: 13.06. 19:00 | B7: 13/06/2026 | C7: 19:00 | D7: Brasil | F7: x | H7: Marrocos
A8: 13.06. 22:00 | B8: 13/06/2026 | C8: 22:00 | D8: Haiti | F8: x | H8: Escócia | J8: Pagar Bolão até 09/06/2026 | K8: 30
A9: 14.06. 01:00 | B9: 14/06/2026 | C9: 01:00 | D9: Austrália | F9: x | H9: Turquia
A10: 14.06. 14:00 | B10: 14/06/2026 | C10: 14:00 | D10: Alemanha | F10: x | H10: Curaçau
A11: 14.06. 17:00 | B11: 14/06/2026 | C11: 17:00 | D11: Países Baixos | F11: x | H11: Japão
A12: 14.06. 20:00 | B12: 14/06/2026 | C12: 20:00 | D12: Costa do Marfim | F12: x | H12: Equador
A13: 14.06. 23:00 | B13: 14/06/2026 | C13: 23:00 | D13: Suécia | F13: x | H13: Tunísia
A14: 15.06. 13:00 | B14: 15/06/2026 | C14: 13:00 | D14: Espanha | F14: x | H14: Cabo Verde
A15: 15.06. 16:00 | B15: 15/06/2026 | C15: 16:00 | D15: Bélgica | F15: x | H15: Egito
A16: 15.06. 19:00 | B16: 15/06/2026 | C16: 19:00 | D16: Arábia Saudita | F16: x | H16: Uruguai
A17: 15.06. 22:00 | B17: 15/06/2026 | C17: 22:00 | D17: Irã | F17: x | H17: Nova Zelândia
A18: 16.06. 16:00 | B18: 16/06/2026 | C18: 16:00 | D18: França | F18: x | H18: Senegal
A19: 16.06. 19:00 | B19: 16/06/2026 | C19: 19:00 | D19: Iraque | F19: x | H19: Noruega
A20: 16.06. 22:00 | B20: 16/06/2026 | C20: 22:00 | D20: Argentina | F20: x | H20: Argélia
... A73: 27.06. 23:00 | B73: 27/06/2026 | C73: 23:00 | D73: Jordânia | F73: x | H73: Argentina

Sheet Macro Palpite
A1: Hora-Data | B1: Data | C1: Horário | D1: Mandante | E1: Placar Mandante | F1: x | G1: Placar Visitante | H1: Visitante | I1: Pontuação | K1: Pontuação
A2: 11.06. 16:00 | B2: 11/06/2026 | C2: 16:00 | D2: México | F2: x | H2: África do Sul | I2: =IF( AND(Tabela_33[[#This Row],[Placar Mandante]]=Tabela_3[[#This Row],[Placar Mandante]], Tabela_33[[#This Row],[Placar Visitante]]=Tabela_3[[#This Row],[Placar Visitante]]), 3, IF( SIGN(Tabela_33[[#This Row],[Placar Mandante]]-Tabela_33[[#This Row],[Placar Visitante]])= SIGN(Tabela_3[[#This Row],[Placar Mandante]]-Tabela_3[[#This Row],[Placar Visitante]]), 1, 0 )) -> 3 | K2: =SUM(Tabela_33[Pontuação]) -> 216
A3: 11.06. 23:00 | B3: 11/06/2026 | C3: 23:00 | D3: Coreia do Sul | F3: x | H3: Republica Tcheca | I3: =IF( AND(Tabela_33[[#This Row],[Placar Mandante]]=Tabela_3[[#This Row],[Placar Mandante]], Tabela_33[[#This Row],[Placar Visitante]]=Tabela_3[[#This Row],[Placar Visitante]]), 3, IF( SIGN(Tabela_33[[#This Row],[Placar Mandante]]-Tabela_33[[#This Row],[Placar Visitante]])= SIGN(Tabela_3[[#This Row],[Placar Mandante]]-Tabela_3[[#This Row],[Placar Visitante]]), 1, 0 )) -> 3
A4: 12.06. 16:00 | B4: 12/06/2026 | C4: 16:00 | D4: Canadá | F4: x | H4: Bósnia e Herzegovina | I4: =IF( AND(Tabela_33[[#This Row],[Placar Mandante]]=Tabela_3[[#This Row],[Placar Mandante]], Tabela_33[[#This Row],[Placar Visitante]]=Tabela_3[[#This Row],[Placar Visitante]]), 3, IF( SIGN(Tabela_33[[#This Row],[Placar Mandante]]-Tabela_33[[#This Row],[Placar Visitante]])= SIGN(Tabela_3[[#This Row],[Placar Mandante]]-Tabela_3[[#This Row],[Placar Visitante]]), 1, 0 )) -> 3
A5: 12.06. 22:00 | B5: 12/06/2026 | C5: 22:00 | D5: EUA | F5: x | H5: Paraguai | I5: =IF( AND(Tabela_33[[#This Row],[Placar Mandante]]=Tabela_3[[#This Row],[Placar Mandante]], Tabela_33[[#This Row],[Placar Visitante]]=Tabela_3[[#This Row],[Placar Visitante]]), 3, IF( SIGN(Tabela_33[[#This Row],[Placar Mandante]]-Tabela_33[[#This Row],[Placar Visitante]])= SIGN(Tabela_3[[#This Row],[Placar Mandante]]-Tabela_3[[#This Row],[Placar Visitante]]), 1, 0 )) -> 3
A6: 13.06. 16:00 | B6: 13/06/2026 | C6: 16:00 | D6: Catar | F6: x | H6: Suíça | I6: =IF( AND(Tabela_33[[#This Row],[Placar Mandante]]=Tabela_3[[#This Row],[Placar Mandante]], Tabela_33[[#This Row],[Placar Visitante]]=Tabela_3[[#This Row],[Placar Visitante]]), 3, IF( SIGN(Tabela_33[[#This Row],[Placar Mandante]]-Tabela_33[[#This Row],[Placar Visitante]])= SIGN(Tabela_3[[#This Row],[Placar Mandante]]-Tabela_3[[#This Row],[Placar Visitante]]), 1, 0 )) -> 3
A7: 13.06. 19:00 | B7: 13/06/2026 | C7: 19:00 | D7: Brasil | F7: x | H7: Marrocos | I7: =IF( AND(Tabela_33[[#This Row],[Placar Mandante]]=Tabela_3[[#This Row],[Placar Mandante]], Tabela_33[[#This Row],[Placar Visitante]]=Tabela_3[[#This Row],[Placar Visitante]]), 3, IF( SIGN(Tabela_33[[#This Row],[Placar Mandante]]-Tabela_33[[#This Row],[Placar Visitante]])= SIGN(Tabela_3[[#This Row],[Placar Mandante]]-Tabela_3[[#This Row],[Placar Visitante]]), 1, 0 )) -> 3
A8: 13.06. 22:00 | B8: 13/06/2026 | C8: 22:00 | D8: Haiti | F8: x | H8: Escócia | I8: =IF( AND(Tabela_33[[#This Row],[Placar Mandante]]=Tabela_3[[#This Row],[Placar Mandante]], Tabela_33[[#This Row],[Placar Visitante]]=Tabela_3[[#This Row],[Placar Visitante]]), 3, IF( SIGN(Tabela_33[[#This Row],[Placar Mandante]]-Tabela_33[[#This Row],[Placar Visitante]])= SIGN(Tabela_3[[#This Row],[Placar Mandante]]-Tabela_3[[#This Row],[Placar Visitante]]), 1, 0 )) -> 3
A9: 14.06. 01:00 | B9: 14/06/2026 | C9: 01:00 | D9: Austrália | F9: x | H9: Turquia | I9: =IF( AND(Tabela_33[[#This Row],[Placar Mandante]]=Tabela_3[[#This Row],[Placar Mandante]], Tabela_33[[#This Row],[Placar Visitante]]=Tabela_3[[#This Row],[Placar Visitante]]), 3, IF( SIGN(Tabela_33[[#This Row],[Placar Mandante]]-Tabela_33[[#This Row],[Placar Visitante]])= SIGN(Tabela_3[[#This Row],[Placar Mandante]]-Tabela_3[[#This Row],[Placar Visitante]]), 1, 0 )) -> 3
A10: 14.06. 14:00 | B10: 14/06/2026 | C10: 14:00 | D10: Alemanha | F10: x | H10: Curaçau | I10: =IF( AND(Tabela_33[[#This Row],[Placar Mandante]]=Tabela_3[[#This Row],[Placar Mandante]], Tabela_33[[#This Row],[Placar Visitante]]=Tabela_3[[#This Row],[Placar Visitante]]), 3, IF( SIGN(Tabela_33[[#This Row],[Placar Mandante]]-Tabela_33[[#This Row],[Placar Visitante]])= SIGN(Tabela_3[[#This Row],[Placar Mandante]]-Tabela_3[[#This Row],[Placar Visitante]]), 1, 0 )) -> 3
A11: 14.06. 17:00 | B11: 14/06/2026 | C11: 17:00 | D11: Países Baixos | F11: x | H11: Japão | I11: =IF( AND(Tabela_33[[#This Row],[Placar Mandante]]=Tabela_3[[#This Row],[Placar Mandante]], Tabela_33[[#This Row],[Placar Visitante]]=Tabela_3[[#This Row],[Placar Visitante]]), 3, IF( SIGN(Tabela_33[[#This Row],[Placar Mandante]]-Tabela_33[[#This Row],[Placar Visitante]])= SIGN(Tabela_3[[#This Row],[Placar Mandante]]-Tabela_3[[#This Row],[Placar Visitante]]), 1, 0 )) -> 3
A12: 14.06. 20:00 | B12: 14/06/2026 | C12: 20:00 | D12: Costa do Marfim | F12: x | H12: Equador | I12: =IF( AND(Tabela_33[[#This Row],[Placar Mandante]]=Tabela_3[[#This Row],[Placar Mandante]], Tabela_33[[#This Row],[Placar Visitante]]=Tabela_3[[#This Row],[Placar Visitante]]), 3, IF( SIGN(Tabela_33[[#This Row],[Placar Mandante]]-Tabela_33[[#This Row],[Placar Visitante]])= SIGN(Tabela_3[[#This Row],[Placar Mandante]]-Tabela_3[[#This Row],[Placar Visitante]]), 1, 0 )) -> 3
A13: 14.06. 23:00 | B13: 14/06/2026 | C13: 23:00 | D13: Suécia | F13: x | H13: Tunísia | I13: =IF( AND(Tabela_33[[#This Row],[Placar Mandante]]=Tabela_3[[#This Row],[Placar Mandante]], Tabela_33[[#This Row],[Placar Visitante]]=Tabela_3[[#This Row],[Placar Visitante]]), 3, IF( SIGN(Tabela_33[[#This Row],[Placar Mandante]]-Tabela_33[[#This Row],[Placar Visitante]])= SIGN(Tabela_3[[#This Row],[Placar Mandante]]-Tabela_3[[#This Row],[Placar Visitante]]), 1, 0 )) -> 3
A14: 15.06. 13:00 | B14: 15/06/2026 | C14: 13:00 | D14: Espanha | F14: x | H14: Cabo Verde | I14: =IF( AND(Tabela_33[[#This Row],[Placar Mandante]]=Tabela_3[[#This Row],[Placar Mandante]], Tabela_33[[#This Row],[Placar Visitante]]=Tabela_3[[#This Row],[Placar Visitante]]), 3, IF( SIGN(Tabela_33[[#This Row],[Placar Mandante]]-Tabela_33[[#This Row],[Placar Visitante]])= SIGN(Tabela_3[[#This Row],[Placar Mandante]]-Tabela_3[[#This Row],[Placar Visitante]]), 1, 0 )) -> 3
... A73: 27.06. 23:00 | B73: 27/06/2026 | C73: 23:00 | D73: Jordânia | F73: x | H73: Argentina | I73: =IF( AND(Tabela_33[[#This Row],[Placar Mandante]]=Tabela_3[[#This Row],[Placar Mandante]], Tabela_33[[#This Row],[Placar Visitante]]=Tabela_3[[#This Row],[Placar Visitante]]), 3, IF( SIGN(Tabela_33[[#This Row],[Placar Mandante]]-Tabela_33[[#This Row],[Placar Visitante]])= SIGN(Tabela_3[[#This Row],[Placar Mandante]]-Tabela_3[[#This Row],[Placar Visitante]]), 1, 0 )) -> 3

Sheet Agnaldo
A1: Hora-Data | B1: Data | C1: Horário | D1: Mandante | E1: Placar Mandante | F1: x | G1: Placar Visitante | H1: Visitante | I1: Pontuação | K1: Pontuação
A2: 11.06. 16:00 | B2: 11/06/2026 | C2: 16:00 | D2: México | E2: 2 | F2: x | G2: 0 | H2: África do Sul | I2: =IF(OR(Tabela_33410[[#This Row],[Placar Mandante]]="",Tabela_33410[[#This Row],[Placar Visitante]]="",Tabela_3[[#This Row],[Placar Mandante]]="",Tabela_3[[#This Row],[Placar Visitante]]=""),0, IF(AND(Tabela_33410[[#This Row],[Placar Mandante]]=Tabela_3[[#This Row],[Placar Mandante]],Tabela_33410[[#This Row],[Placar Visitante]]=Tabela_3[[#This Row],[Placar Visitante]]),3, IF(SIGN(Tabela_33410[[#This Row],[Placar Mandante]]-Tabela_33410[[#This Row],[Placar Visitante]])=SIGN(Tabela_3[[#This Row],[Placar Mandante]]-Tabela_3[[#This Row],[Placar Visitante]]),1,0))) -> 0 | K2: =SUM(Tabela_33410[Pontuação]) -> 0
A3: 11.06. 23:00 | B3: 11/06/2026 | C3: 23:00 | D3: Coreia do Sul | E3: 1 | F3: x | G3: 1 | H3: Republica Tcheca | I3: =IF(OR(Tabela_33410[[#This Row],[Placar Mandante]]="",Tabela_33410[[#This Row],[Placar Visitante]]="",Tabela_3[[#This Row],[Placar Mandante]]="",Tabela_3[[#This Row],[Placar Visitante]]=""),0, IF(AND(Tabela_33410[[#This Row],[Placar Mandante]]=Tabela_3[[#This Row],[Placar Mandante]],Tabela_33410[[#This Row],[Placar Visitante]]=Tabela_3[[#This Row],[Placar Visitante]]),3, IF(SIGN(Tabela_33410[[#This Row],[Placar Mandante]]-Tabela_33410[[#This Row],[Placar Visitante]])=SIGN(Tabela_3[[#This Row],[Placar Mandante]]-Tabela_3[[#This Row],[Placar Visitante]]),1,0))) -> 0
A4: 12.06. 16:00 | B4: 12/06/2026 | C4: 16:00 | D4: Canadá | E4: 2 | F4: x | G4: 1 | H4: Bósnia e Herzegovina | I4: =IF(OR(Tabela_33410[[#This Row],[Placar Mandante]]="",Tabela_33410[[#This Row],[Placar Visitante]]="",Tabela_3[[#This Row],[Placar Mandante]]="",Tabela_3[[#This Row],[Placar Visitante]]=""),0, IF(AND(Tabela_33410[[#This Row],[Placar Mandante]]=Tabela_3[[#This Row],[Placar Mandante]],Tabela_33410[[#This Row],[Placar Visitante]]=Tabela_3[[#This Row],[Placar Visitante]]),3, IF(SIGN(Tabela_33410[[#This Row],[Placar Mandante]]-Tabela_33410[[#This Row],[Placar Visitante]])=SIGN(Tabela_3[[#This Row],[Placar Mandante]]-Tabela_3[[#This Row],[Placar Visitante]]),1,0))) -> 0
A5: 12.06. 22:00 | B5: 12/06/2026 | C5: 22:00 | D5: EUA | E5: 1 | F5: x | G5: 0 | H5: Paraguai | I5: =IF(OR(Tabela_33410[[#This Row],[Placar Mandante]]="",Tabela_33410[[#This Row],[Placar Visitante]]="",Tabela_3[[#This Row],[Placar Mandante]]="",Tabela_3[[#This Row],[Placar Visitante]]=""),0, IF(AND(Tabela_33410[[#This Row],[Placar Mandante]]=Tabela_3[[#This Row],[Placar Mandante]],Tabela_33410[[#This Row],[Placar Visitante]]=Tabela_3[[#This Row],[Placar Visitante]]),3, IF(SIGN(Tabela_33410[[#This Row],[Placar Mandante]]-Tabela_33410[[#This Row],[Placar Visitante]])=SIGN(Tabela_3[[#This Row],[Placar Mandante]]-Tabela_3[[#This Row],[Placar Visitante]]),1,0))) -> 0
A6: 13.06. 16:00 | B6: 13/06/2026 | C6: 16:00 | D6: Catar | E6: 0 | F6: x | G6: 2 | H6: Suíça | I6: =IF(OR(Tabela_33410[[#This Row],[Placar Mandante]]="",Tabela_33410[[#This Row],[Placar Visitante]]="",Tabela_3[[#This Row],[Placar Mandante]]="",Tabela_3[[#This Row],[Placar Visitante]]=""),0, IF(AND(Tabela_33410[[#This Row],[Placar Mandante]]=Tabela_3[[#This Row],[Placar Mandante]],Tabela_33410[[#This Row],[Placar Visitante]]=Tabela_3[[#This Row],[Placar Visitante]]),3, IF(SIGN(Tabela_33410[[#This Row],[Placar Mandante]]-Tabela_33410[[#This Row],[Placar Visitante]])=SIGN(Tabela_3[[#This Row],[Placar Mandante]]-Tabela_3[[#This Row],[Placar Visitante]]),1,0))) -> 0
A7: 13.06. 19:00 | B7: 13/06/2026 | C7: 19:00 | D7: Brasil | E7: 2 | F7: x | G7: 0 | H7: Marrocos | I7: =IF(OR(Tabela_33410[[#This Row],[Placar Mandante]]="",Tabela_33410[[#This Row],[Placar Visitante]]="",Tabela_3[[#This Row],[Placar Mandante]]="",Tabela_3[[#This Row],[Placar Visitante]]=""),0, IF(AND(Tabela_33410[[#This Row],[Placar Mandante]]=Tabela_3[[#This Row],[Placar Mandante]],Tabela_33410[[#This Row],[Placar Visitante]]=Tabela_3[[#This Row],[Placar Visitante]]),3, IF(SIGN(Tabela_33410[[#This Row],[Placar Mandante]]-Tabela_33410[[#This Row],[Placar Visitante]])=SIGN(Tabela_3[[#This Row],[Placar Mandante]]-Tabela_3[[#This Row],[Placar Visitante]]),1,0))) -> 0
A8: 13.06. 22:00 | B8: 13/06/2026 | C8: 22:00 | D8: Haiti | E8: 0 | F8: x | G8: 2 | H8: Escócia | I8: =IF(OR(Tabela_33410[[#This Row],[Placar Mandante]]="",Tabela_33410[[#This Row],[Placar Visitante]]="",Tabela_3[[#This Row],[Placar Mandante]]="",Tabela_3[[#This Row],[Placar Visitante]]=""),0, IF(AND(Tabela_33410[[#This Row],[Placar Mandante]]=Tabela_3[[#This Row],[Placar Mandante]],Tabela_33410[[#This Row],[Placar Visitante]]=Tabela_3[[#This Row],[Placar Visitante]]),3, IF(SIGN(Tabela_33410[[#This Row],[Placar Mandante]]-Tabela_33410[[#This Row],[Placar Visitante]])=SIGN(Tabela_3[[#This Row],[Placar Mandante]]-Tabela_3[[#This Row],[Placar Visitante]]),1,0))) -> 0
A9: 14.06. 01:00 | B9: 14/06/2026 | C9: 01:00 | D9: Austrália | E9: 1 | F9: x | G9: 2 | H9: Turquia | I9: =IF(OR(Tabela_33410[[#This Row],[Placar Mandante]]="",Tabela_33410[[#This Row],[Placar Visitante]]="",Tabela_3[[#This Row],[Placar Mandante]]="",Tabela_3[[#This Row],[Placar Visitante]]=""),0, IF(AND(Tabela_33410[[#This Row],[Placar Mandante]]=Tabela_3[[#This Row],[Placar Mandante]],Tabela_33410[[#This Row],[Placar Visitante]]=Tabela_3[[#This Row],[Placar Visitante]]),3, IF(SIGN(Tabela_33410[[#This Row],[Placar Mandante]]-Tabela_33410[[#This Row],[Placar Visitante]])=SIGN(Tabela_3[[#This Row],[Placar Mandante]]-Tabela_3[[#This Row],[Placar Visitante]]),1,0))) -> 0
A10: 14.06. 14:00 | B10: 14/06/2026 | C10: 14:00 | D10: Alemanha | E10: 3 | F10: x | G10: 0 | H10: Curaçau | I10: =IF(OR(Tabela_33410[[#This Row],[Placar Mandante]]="",Tabela_33410[[#This Row],[Placar Visitante]]="",Tabela_3[[#This Row],[Placar Mandante]]="",Tabela_3[[#This Row],[Placar Visitante]]=""),0, IF(AND(Tabela_33410[[#This Row],[Placar Mandante]]=Tabela_3[[#This Row],[Placar Mandante]],Tabela_33410[[#This Row],[Placar Visitante]]=Tabela_3[[#This Row],[Placar Visitante]]),3, IF(SIGN(Tabela_33410[[#This Row],[Placar Mandante]]-Tabela_33410[[#This Row],[Placar Visitante]])=SIGN(Tabela_3[[#This Row],[Placar Mandante]]-Tabela_3[[#This Row],[Placar Visitante]]),1,0))) -> 0
A11: 14.06. 17:00 | B11: 14/06/2026 | C11: 17:00 | D11: Países Baixos | E11: 2 | F11: x | G11: 1 | H11: Japão | I11: =IF(OR(Tabela_33410[[#This Row],[Placar Mandante]]="",Tabela_33410[[#This Row],[Placar Visitante]]="",Tabela_3[[#This Row],[Placar Mandante]]="",Tabela_3[[#This Row],[Placar Visitante]]=""),0, IF(AND(Tabela_33410[[#This Row],[Placar Mandante]]=Tabela_3[[#This Row],[Placar Mandante]],Tabela_33410[[#This Row],[Placar Visitante]]=Tabela_3[[#This Row],[Placar Visitante]]),3, IF(SIGN(Tabela_33410[[#This Row],[Placar Mandante]]-Tabela_33410[[#This Row],[Placar Visitante]])=SIGN(Tabela_3[[#This Row],[Placar Mandante]]-Tabela_3[[#This Row],[Placar Visitante]]),1,0))) -> 0
A12: 14.06. 20:00 | B12: 14/06/2026 | C12: 20:00 | D12: Costa do Marfim | E12: 2 | F12: x | G12: 1 | H12: Equador | I12: =IF(OR(Tabela_33410[[#This Row],[Placar Mandante]]="",Tabela_33410[[#This Row],[Placar Visitante]]="",Tabela_3[[#This Row],[Placar Mandante]]="",Tabela_3[[#This Row],[Placar Visitante]]=""),0, IF(AND(Tabela_33410[[#This Row],[Placar Mandante]]=Tabela_3[[#This Row],[Placar Mandante]],Tabela_33410[[#This Row],[Placar Visitante]]=Tabela_3[[#This Row],[Placar Visitante]]),3, IF(SIGN(Tabela_33410[[#This Row],[Placar Mandante]]-Tabela_33410[[#This Row],[Placar Visitante]])=SIGN(Tabela_3[[#This Row],[Placar Mandante]]-Tabela_3[[#This Row],[Placar Visitante]]),1,0))) -> 0
A13: 14.06. 23:00 | B13: 14/06/2026 | C13: 23:00 | D13: Suécia | E13: 2 | F13: x | G13: 1 | H13: Tunísia | I13: =IF(OR(Tabela_33410[[#This Row],[Placar Mandante]]="",Tabela_33410[[#This Row],[Placar Visitante]]="",Tabela_3[[#This Row],[Placar Mandante]]="",Tabela_3[[#This Row],[Placar Visitante]]=""),0, IF(AND(Tabela_33410[[#This Row],[Placar Mandante]]=Tabela_3[[#This Row],[Placar Mandante]],Tabela_33410[[#This Row],[Placar Visitante]]=Tabela_3[[#This Row],[Placar Visitante]]),3, IF(SIGN(Tabela_33410[[#This Row],[Placar Mandante]]-Tabela_33410[[#This Row],[Placar Visitante]])=SIGN(Tabela_3[[#This Row],[Placar Mandante]]-Tabela_3[[#This Row],[Placar Visitante]]),1,0))) -> 0
A14: 15.06. 13:00 | B14: 15/06/2026 | C14: 13:00 | D14: Espanha | E14: 4 | F14: x | G14: 0 | H14: Cabo Verde | I14: =IF(OR(Tabela_33410[[#This Row],[Placar Mandante]]="",Tabela_33410[[#This Row],[Placar Visitante]]="",Tabela_3[[#This Row],[Placar Mandante]]="",Tabela_3[[#This Row],[Placar Visitante]]=""),0, IF(AND(Tabela_33410[[#This Row],[Placar Mandante]]=Tabela_3[[#This Row],[Placar Mandante]],Tabela_33410[[#This Row],[Placar Visitante]]=Tabela_3[[#This Row],[Placar Visitante]]),3, IF(SIGN(Tabela_33410[[#This Row],[Placar Mandante]]-Tabela_33410[[#This Row],[Placar Visitante]])=SIGN(Tabela_3[[#This Row],[Placar Mandante]]-Tabela_3[[#This Row],[Placar Visitante]]),1,0))) -> 0
... A73: 27.06. 23:00 | B73: 27/06/2026 | C73: 23:00 | D73: Jordânia | E73: 0 | F73: x | G73: 3 | H73: Argentina | I73: =IF(OR(Tabela_33410[[#This Row],[Placar Mandante]]="",Tabela_33410[[#This Row],[Placar Visitante]]="",Tabela_3[[#This Row],[Placar Mandante]]="",Tabela_3[[#This Row],[Placar Visitante]]=""),0, IF(AND(Tabela_33410[[#This Row],[Placar Mandante]]=Tabela_3[[#This Row],[Placar Mandante]],Tabela_33410[[#This Row],[Placar Visitante]]=Tabela_3[[#This Row],[Placar Visitante]]),3, IF(SIGN(Tabela_33410[[#This Row],[Placar Mandante]]-Tabela_33410[[#This Row],[Placar Visitante]])=SIGN(Tabela_3[[#This Row],[Placar Mandante]]-Tabela_3[[#This Row],[Placar Visitante]]),1,0))) -> 0

Sheet Alessandro Pignata
A1: Hora-Data | B1: Data | C1: Horário | D1: Mandante | E1: Placar Mandante | F1: x | G1: Placar Visitante | H1: Visitante | I1: Pontuação | K1: Pontuação
A2: 11.06. 16:00 | B2: 11/06/2026 | C2: 16:00 | D2: México | E2: 2 | F2: x | G2: 0 | H2: África do Sul | I2: =IF(OR(Tabela_3334[[#This Row],[Placar Mandante]]="",Tabela_3334[[#This Row],[Placar Visitante]]="",Tabela_3[[#This Row],[Placar Mandante]]="",Tabela_3[[#This Row],[Placar Visitante]]=""),0, IF(AND(Tabela_3334[[#This Row],[Placar Mandante]]=Tabela_3[[#This Row],[Placar Mandante]],Tabela_3334[[#This Row],[Placar Visitante]]=Tabela_3[[#This Row],[Placar Visitante]]),3, IF(SIGN(Tabela_3334[[#This Row],[Placar Mandante]]-Tabela_3334[[#This Row],[Placar Visitante]])=SIGN(Tabela_3[[#This Row],[Placar Mandante]]-Tabela_3[[#This Row],[Placar Visitante]]),1,0))) -> 0 | K2: =SUM(Tabela_3334[Pontuação]) -> 0
A3: 11.06. 23:00 | B3: 11/06/2026 | C3: 23:00 | D3: Coreia do Sul | E3: 1 | F3: x | G3: 3 | H3: Republica Tcheca | I3: =IF(OR(Tabela_3334[[#This Row],[Placar Mandante]]="",Tabela_3334[[#This Row],[Placar Visitante]]="",Tabela_3[[#This Row],[Placar Mandante]]="",Tabela_3[[#This Row],[Placar Visitante]]=""),0, IF(AND(Tabela_3334[[#This Row],[Placar Mandante]]=Tabela_3[[#This Row],[Placar Mandante]],Tabela_3334[[#This Row],[Placar Visitante]]=Tabela_3[[#This Row],[Placar Visitante]]),3, IF(SIGN(Tabela_3334[[#This Row],[Placar Mandante]]-Tabela_3334[[#This Row],[Placar Visitante]])=SIGN(Tabela_3[[#This Row],[Placar Mandante]]-Tabela_3[[#This Row],[Placar Visitante]]),1,0))) -> 0
A4: 12.06. 16:00 | B4: 12/06/2026 | C4: 16:00 | D4: Canadá | E4: 0 | F4: x | G4: 3 | H4: Bósnia e Herzegovina | I4: =IF(OR(Tabela_3334[[#This Row],[Placar Mandante]]="",Tabela_3334[[#This Row],[Placar Visitante]]="",Tabela_3[[#This Row],[Placar Mandante]]="",Tabela_3[[#This Row],[Placar Visitante]]=""),0, IF(AND(Tabela_3334[[#This Row],[Placar Mandante]]=Tabela_3[[#This Row],[Placar Mandante]],Tabela_3334[[#This Row],[Placar Visitante]]=Tabela_3[[#This Row],[Placar Visitante]]),3, IF(SIGN(Tabela_3334[[#This Row],[Placar Mandante]]-Tabela_3334[[#This Row],[Placar Visitante]])=SIGN(Tabela_3[[#This Row],[Placar Mandante]]-Tabela_3[[#This Row],[Placar Visitante]]),1,0))) -> 0
A5: 12.06. 22:00 | B5: 12/06/2026 | C5: 22:00 | D5: EUA | E5: 2 | F5: x | G5: 3 | H5: Paraguai | I5: =IF(OR(Tabela_3334[[#This Row],[Placar Mandante]]="",Tabela_3334[[#This Row],[Placar Visitante]]="",Tabela_3[[#This Row],[Placar Mandante]]="",Tabela_3[[#This Row],[Placar Visitante]]=""),0, IF(AND(Tabela_3334[[#This Row],[Placar Mandante]]=Tabela_3[[#This Row],[Placar Mandante]],Tabela_3334[[#This Row],[Placar Visitante]]=Tabela_3[[#This Row],[Placar Visitante]]),3, IF(SIGN(Tabela_3334[[#This Row],[Placar Mandante]]-Tabela_3334[[#This Row],[Placar Visitante]])=SIGN(Tabela_3[[#This Row],[Placar Mandante]]-Tabela_3[[#This Row],[Placar Visitante]]),1,0))) -> 0
A6: 13.06. 16:00 | B6: 13/06/2026 | C6: 16:00 | D6: Catar | E6: 0 | F6: x | G6: 1 | H6: Suíça | I6: =IF(OR(Tabela_3334[[#This Row],[Placar Mandante]]="",Tabela_3334[[#This Row],[Placar Visitante]]="",Tabela_3[[#This Row],[Placar Mandante]]="",Tabela_3[[#This Row],[Placar Visitante]]=""),0, IF(AND(Tabela_3334[[#This Row],[Placar Mandante]]=Tabela_3[[#This Row],[Placar Mandante]],Tabela_3334[[#This Row],[Placar Visitante]]=Tabela_3[[#This Row],[Placar Visitante]]),3, IF(SIGN(Tabela_3334[[#This Row],[Placar Mandante]]-Tabela_3334[[#This Row],[Placar Visitante]])=SIGN(Tabela_3[[#This Row],[Placar Mandante]]-Tabela_3[[#This Row],[Placar Visitante]]),1,0))) -> 0
A7: 13.06. 19:00 | B7: 13/06/2026 | C7: 19:00 | D7: Brasil | E7: 2 | F7: x | G7: 1 | H7: Marrocos | I7: =IF(OR(Tabela_3334[[#This Row],[Placar Mandante]]="",Tabela_3334[[#This Row],[Placar Visitante]]="",Tabela_3[[#This Row],[Placar Mandante]]="",Tabela_3[[#This Row],[Placar Visitante]]=""),0, IF(AND(Tabela_3334[[#This Row],[Placar Mandante]]=Tabela_3[[#This Row],[Placar Mandante]],Tabela_3334[[#This Row],[Placar Visitante]]=Tabela_3[[#This Row],[Placar Visitante]]),3, IF(SIGN(Tabela_3334[[#This Row],[Placar Mandante]]-Tabela_3334[[#This Row],[Placar Visitante]])=SIGN(Tabela_3[[#This Row],[Placar Mandante]]-Tabela_3[[#This Row],[Placar Visitante]]),1,0))) -> 0
A8: 13.06. 22:00 | B8: 13/06/2026 | C8: 22:00 | D8: Haiti | E8: 0 | F8: x | G8: 3 | H8: Escócia | I8: =IF(OR(Tabela_3334[[#This Row],[Placar Mandante]]="",Tabela_3334[[#This Row],[Placar Visitante]]="",Tabela_3[[#This Row],[Placar Mandante]]="",Tabela_3[[#This Row],[Placar Visitante]]=""),0, IF(AND(Tabela_3334[[#This Row],[Placar Mandante]]=Tabela_3[[#This Row],[Placar Mandante]],Tabela_3334[[#This Row],[Placar Visitante]]=Tabela_3[[#This Row],[Placar Visitante]]),3, IF(SIGN(Tabela_3334[[#This Row],[Placar Mandante]]-Tabela_3334[[#This Row],[Placar Visitante]])=SIGN(Tabela_3[[#This Row],[Placar Mandante]]-Tabela_3[[#This Row],[Placar Visitante]]),1,0))) -> 0
A9: 14.06. 01:00 | B9: 14/06/2026 | C9: 01:00 | D9: Austrália | E9: 0 | F9: x | G9: 4 | H9: Turquia | I9: =IF(OR(Tabela_3334[[#This Row],[Placar Mandante]]="",Tabela_3334[[#This Row],[Placar Visitante]]="",Tabela_3[[#This Row],[Placar Mandante]]="",Tabela_3[[#This Row],[Placar Visitante]]=""),0, IF(AND(Tabela_3334[[#This Row],[Placar Mandante]]=Tabela_3[[#This Row],[Placar Mandante]],Tabela_3334[[#This Row],[Placar Visitante]]=Tabela_3[[#This Row],[Placar Visitante]]),3, IF(SIGN(Tabela_3334[[#This Row],[Placar Mandante]]-Tabela_3334[[#This Row],[Placar Visitante]])=SIGN(Tabela_3[[#This Row],[Placar Mandante]]-Tabela_3[[#This Row],[Placar Visitante]]),1,0))) -> 0
A10: 14.06. 14:00 | B10: 14/06/2026 | C10: 14:00 | D10: Alemanha | E10: 5 | F10: x | G10: 1 | H10: Curaçau | I10: =IF(OR(Tabela_3334[[#This Row],[Placar Mandante]]="",Tabela_3334[[#This Row],[Placar Visitante]]="",Tabela_3[[#This Row],[Placar Mandante]]="",Tabela_3[[#This Row],[Placar Visitante]]=""),0, IF(AND(Tabela_3334[[#This Row],[Placar Mandante]]=Tabela_3[[#This Row],[Placar Mandante]],Tabela_3334[[#This Row],[Placar Visitante]]=Tabela_3[[#This Row],[Placar Visitante]]),3, IF(SIGN(Tabela_3334[[#This Row],[Placar Mandante]]-Tabela_3334[[#This Row],[Placar Visitante]])=SIGN(Tabela_3[[#This Row],[Placar Mandante]]-Tabela_3[[#This Row],[Placar Visitante]]),1,0))) -> 0
A11: 14.06. 17:00 | B11: 14/06/2026 | C11: 17:00 | D11: Países Baixos | E11: 1 | F11: x | G11: 0 | H11: Japão | I11: =IF(OR(Tabela_3334[[#This Row],[Placar Mandante]]="",Tabela_3334[[#This Row],[Placar Visitante]]="",Tabela_3[[#This Row],[Placar Mandante]]="",Tabela_3[[#This Row],[Placar Visitante]]=""),0, IF(AND(Tabela_3334[[#This Row],[Placar Mandante]]=Tabela_3[[#This Row],[Placar Mandante]],Tabela_3334[[#This Row],[Placar Visitante]]=Tabela_3[[#This Row],[Placar Visitante]]),3, IF(SIGN(Tabela_3334[[#This Row],[Placar Mandante]]-Tabela_3334[[#This Row],[Placar Visitante]])=SIGN(Tabela_3[[#This Row],[Placar Mandante]]-Tabela_3[[#This Row],[Placar Visitante]]),1,0))) -> 0
A12: 14.06. 20:00 | B12: 14/06/2026 | C12: 20:00 | D12: Costa do Marfim | E12: 3 | F12: x | G12: 1 | H12: Equador | I12: =IF(OR(Tabela_3334[[#This Row],[Placar Mandante]]="",Tabela_3334[[#This Row],[Placar Visitante]]="",Tabela_3[[#This Row],[Placar Mandante]]="",Tabela_3[[#This Row],[Placar Visitante]]=""),0, IF(AND(Tabela_3334[[#This Row],[Placar Mandante]]=Tabela_3[[#This Row],[Placar Mandante]],Tabela_3334[[#This Row],[Placar Visitante]]=Tabela_3[[#This Row],[Placar Visitante]]),3, IF(SIGN(Tabela_3334[[#This Row],[Placar Mandante]]-Tabela_3334[[#This Row],[Placar Visitante]])=SIGN(Tabela_3[[#This Row],[Placar Mandante]]-Tabela_3[[#This Row],[Placar Visitante]]),1,0))) -> 0
A13: 14.06. 23:00 | B13: 14/06/2026 | C13: 23:00 | D13: Suécia | E13: 2 | F13: x | G13: 2 | H13: Tunísia | I13: =IF(OR(Tabela_3334[[#This Row],[Placar Mandante]]="",Tabela_3334[[#This Row],[Placar Visitante]]="",Tabela_3[[#This Row],[Placar Mandante]]="",Tabela_3[[#This Row],[Placar Visitante]]=""),0, IF(AND(Tabela_3334[[#This Row],[Placar Mandante]]=Tabela_3[[#This Row],[Placar Mandante]],Tabela_3334[[#This Row],[Placar Visitante]]=Tabela_3[[#This Row],[Placar Visitante]]),3, IF(SIGN(Tabela_3334[[#This Row],[Placar Mandante]]-Tabela_3334[[#This Row],[Placar Visitante]])=SIGN(Tabela_3[[#This Row],[Placar Mandante]]-Tabela_3[[#This Row],[Placar Visitante]]),1,0))) -> 0
A14: 15.06. 13:00 | B14: 15/06/2026 | C14: 13:00 | D14: Espanha | E14: 3 | F14: x | G14: 0 | H14: Cabo Verde | I14: =IF(OR(Tabela_3334[[#This Row],[Placar Mandante]]="",Tabela_3334[[#This Row],[Placar Visitante]]="",Tabela_3[[#This Row],[Placar Mandante]]="",Tabela_3[[#This Row],[Placar Visitante]]=""),0, IF(AND(Tabela_3334[[#This Row],[Placar Mandante]]=Tabela_3[[#This Row],[Placar Mandante]],Tabela_3334[[#This Row],[Placar Visitante]]=Tabela_3[[#This Row],[Placar Visitante]]),3, IF(SIGN(Tabela_3334[[#This Row],[Placar Mandante]]-Tabela_3334[[#This Row],[Placar Visitante]])=SIGN(Tabela_3[[#This Row],[Placar Mandante]]-Tabela_3[[#This Row],[Placar Visitante]]),1,0))) -> 0
... A73: 27.06. 23:00 | B73: 27/06/2026 | C73: 23:00 | D73: Jordânia | E73: 0 | F73: x | G73: 3 | H73: Argentina | I73: =IF(OR(Tabela_3334[[#This Row],[Placar Mandante]]="",Tabela_3334[[#This Row],[Placar Visitante]]="",Tabela_3[[#This Row],[Placar Mandante]]="",Tabela_3[[#This Row],[Placar Visitante]]=""),0, IF(AND(Tabela_3334[[#This Row],[Placar Mandante]]=Tabela_3[[#This Row],[Placar Mandante]],Tabela_3334[[#This Row],[Placar Visitante]]=Tabela_3[[#This Row],[Placar Visitante]]),3, IF(SIGN(Tabela_3334[[#This Row],[Placar Mandante]]-Tabela_3334[[#This Row],[Placar Visitante]])=SIGN(Tabela_3[[#This Row],[Placar Mandante]]-Tabela_3[[#This Row],[Placar Visitante]]),1,0))) -> 0

Sheet Allan Ribeiro
A1: Hora-Data | B1: Data | C1: Horário | D1: Mandante | E1: Placar Mandante | F1: x | G1: Placar Visitante | H1: Visitante | I1: Pontuação | K1: Pontuação
A2: 11.06. 16:00 | B2: 11/06/2026 | C2: 16:00 | D2: México | E2: 0 | F2: x | G2: 0 | H2: África do Sul | I2: =IF(OR(Tabela_33471[[#This Row],[Placar Mandante]]="",Tabela_33471[[#This Row],[Placar Visitante]]="",Tabela_3[[#This Row],[Placar Mandante]]="",Tabela_3[[#This Row],[Placar Visitante]]=""),0, IF(AND(Tabela_33471[[#This Row],[Placar Mandante]]=Tabela_3[[#This Row],[Placar Mandante]],Tabela_33471[[#This Row],[Placar Visitante]]=Tabela_3[[#This Row],[Placar Visitante]]),3, IF(SIGN(Tabela_33471[[#This Row],[Placar Mandante]]-Tabela_33471[[#This Row],[Placar Visitante]])=SIGN(Tabela_3[[#This Row],[Placar Mandante]]-Tabela_3[[#This Row],[Placar Visitante]]),1,0))) -> 0 | K2: =SUM(Tabela_33471[Pontuação]) -> 0
A3: 11.06. 23:00 | B3: 11/06/2026 | C3: 23:00 | D3: Coreia do Sul | E3: 0 | F3: x | G3: 0 | H3: Republica Tcheca | I3: =IF(OR(Tabela_33471[[#This Row],[Placar Mandante]]="",Tabela_33471[[#This Row],[Placar Visitante]]="",Tabela_3[[#This Row],[Placar Mandante]]="",Tabela_3[[#This Row],[Placar Visitante]]=""),0, IF(AND(Tabela_33471[[#This Row],[Placar Mandante]]=Tabela_3[[#This Row],[Placar Mandante]],Tabela_33471[[#This Row],[Placar Visitante]]=Tabela_3[[#This Row],[Placar Visitante]]),3, IF(SIGN(Tabela_33471[[#This Row],[Placar Mandante]]-Tabela_33471[[#This Row],[Placar Visitante]])=SIGN(Tabela_3[[#This Row],[Placar Mandante]]-Tabela_3[[#This Row],[Placar Visitante]]),1,0))) -> 0
A4: 12.06. 16:00 | B4: 12/06/2026 | C4: 16:00 | D4: Canadá | E4: 1 | F4: x | G4: 0 | H4: Bósnia e Herzegovina | I4: =IF(OR(Tabela_33471[[#This Row],[Placar Mandante]]="",Tabela_33471[[#This Row],[Placar Visitante]]="",Tabela_3[[#This Row],[Placar Mandante]]="",Tabela_3[[#This Row],[Placar Visitante]]=""),0, IF(AND(Tabela_33471[[#This Row],[Placar Mandante]]=Tabela_3[[#This Row],[Placar Mandante]],Tabela_33471[[#This Row],[Placar Visitante]]=Tabela_3[[#This Row],[Placar Visitante]]),3, IF(SIGN(Tabela_33471[[#This Row],[Placar Mandante]]-Tabela_33471[[#This Row],[Placar Visitante]])=SIGN(Tabela_3[[#This Row],[Placar Mandante]]-Tabela_3[[#This Row],[Placar Visitante]]),1,0))) -> 0
A5: 12.06. 22:00 | B5: 12/06/2026 | C5: 22:00 | D5: EUA | E5: 0 | F5: x | G5: 1 | H5: Paraguai | I5: =IF(OR(Tabela_33471[[#This Row],[Placar Mandante]]="",Tabela_33471[[#This Row],[Placar Visitante]]="",Tabela_3[[#This Row],[Placar Mandante]]="",Tabela_3[[#This Row],[Placar Visitante]]=""),0, IF(AND(Tabela_33471[[#This Row],[Placar Mandante]]=Tabela_3[[#This Row],[Placar Mandante]],Tabela_33471[[#This Row],[Placar Visitante]]=Tabela_3[[#This Row],[Placar Visitante]]),3, IF(SIGN(Tabela_33471[[#This Row],[Placar Mandante]]-Tabela_33471[[#This Row],[Placar Visitante]])=SIGN(Tabela_3[[#This Row],[Placar Mandante]]-Tabela_3[[#This Row],[Placar Visitante]]),1,0))) -> 0
A6: 13.06. 16:00 | B6: 13/06/2026 | C6: 16:00 | D6: Catar | E6: 0 | F6: x | G6: 1 | H6: Suíça | I6: =IF(OR(Tabela_33471[[#This Row],[Placar Mandante]]="",Tabela_33471[[#This Row],[Placar Visitante]]="",Tabela_3[[#This Row],[Placar Mandante]]="",Tabela_3[[#This Row],[Placar Visitante]]=""),0, IF(AND(Tabela_33471[[#This Row],[Placar Mandante]]=Tabela_3[[#This Row],[Placar Mandante]],Tabela_33471[[#This Row],[Placar Visitante]]=Tabela_3[[#This Row],[Placar Visitante]]),3, IF(SIGN(Tabela_33471[[#This Row],[Placar Mandante]]-Tabela_33471[[#This Row],[Placar Visitante]])=SIGN(Tabela_3[[#This Row],[Placar Mandante]]-Tabela_3[[#This Row],[Placar Visitante]]),1,0))) -> 0
A7: 13.06. 19:00 | B7: 13/06/2026 | C7: 19:00 | D7: Brasil | E7: 1 | F7: x | G7: 0 | H7: Marrocos | I7: =IF(OR(Tabela_33471[[#This Row],[Placar Mandante]]="",Tabela_33471[[#This Row],[Placar Visitante]]="",Tabela_3[[#This Row],[Placar Mandante]]="",Tabela_3[[#This Row],[Placar Visitante]]=""),0, IF(AND(Tabela_33471[[#This Row],[Placar Mandante]]=Tabela_3[[#This Row],[Placar Mandante]],Tabela_33471[[#This Row],[Placar Visitante]]=Tabela_3[[#This Row],[Placar Visitante]]),3, IF(SIGN(Tabela_33471[[#This Row],[Placar Mandante]]-Tabela_33471[[#This Row],[Placar Visitante]])=SIGN(Tabela_3[[#This Row],[Placar Mandante]]-Tabela_3[[#This Row],[Placar Visitante]]),1,0))) -> 0
A8: 13.06. 22:00 | B8: 13/06/2026 | C8: 22:00 | D8: Haiti | E8: 0 | F8: x | G8: 1 | H8: Escócia | I8: =IF(OR(Tabela_33471[[#This Row],[Placar Mandante]]="",Tabela_33471[[#This Row],[Placar Visitante]]="",Tabela_3[[#This Row],[Placar Mandante]]="",Tabela_3[[#This Row],[Placar Visitante]]=""),0, IF(AND(Tabela_33471[[#This Row],[Placar Mandante]]=Tabela_3[[#This Row],[Placar Mandante]],Tabela_33471[[#This Row],[Placar Visitante]]=Tabela_3[[#This Row],[Placar Visitante]]),3, IF(SIGN(Tabela_33471[[#This Row],[Placar Mandante]]-Tabela_33471[[#This Row],[Placar Visitante]])=SIGN(Tabela_3[[#This Row],[Placar Mandante]]-Tabela_3[[#This Row],[Placar Visitante]]),1,0))) -> 0
A9: 14.06. 01:00 | B9: 14/06/2026 | C9: 01:00 | D9: Austrália | E9: 0 | F9: x | G9: 0 | H9: Turquia | I9: =IF(OR(Tabela_33471[[#This Row],[Placar Mandante]]="",Tabela_33471[[#This Row],[Placar Visitante]]="",Tabela_3[[#This Row],[Placar Mandante]]="",Tabela_3[[#This Row],[Placar Visitante]]=""),0, IF(AND(Tabela_33471[[#This Row],[Placar Mandante]]=Tabela_3[[#This Row],[Placar Mandante]],Tabela_33471[[#This Row],[Placar Visitante]]=Tabela_3[[#This Row],[Placar Visitante]]),3, IF(SIGN(Tabela_33471[[#This Row],[Placar Mandante]]-Tabela_33471[[#This Row],[Placar Visitante]])=SIGN(Tabela_3[[#This Row],[Placar Mandante]]-Tabela_3[[#This Row],[Placar Visitante]]),1,0))) -> 0
A10: 14.06. 14:00 | B10: 14/06/2026 | C10: 14:00 | D10: Alemanha | E10: 1 | F10: x | G10: 0 | H10: Curaçau | I10: =IF(OR(Tabela_33471[[#This Row],[Placar Mandante]]="",Tabela_33471[[#This Row],[Placar Visitante]]="",Tabela_3[[#This Row],[Placar Mandante]]="",Tabela_3[[#This Row],[Placar Visitante]]=""),0, IF(AND(Tabela_33471[[#This Row],[Placar Mandante]]=Tabela_3[[#This Row],[Placar Mandante]],Tabela_33471[[#This Row],[Placar Visitante]]=Tabela_3[[#This Row],[Placar Visitante]]),3, IF(SIGN(Tabela_33471[[#This Row],[Placar Mandante]]-Tabela_33471[[#This Row],[Placar Visitante]])=SIGN(Tabela_3[[#This Row],[Placar Mandante]]-Tabela_3[[#This Row],[Placar Visitante]]),1,0))) -> 0
A11: 14.06. 17:00 | B11: 14/06/2026 | C11: 17:00 | D11: Países Baixos | E11: 1 | F11: x | G11: 0 | H11: Japão | I11: =IF(OR(Tabela_33471[[#This Row],[Placar Mandante]]="",Tabela_33471[[#This Row],[Placar Visitante]]="",Tabela_3[[#This Row],[Placar Mandante]]="",Tabela_3[[#This Row],[Placar Visitante]]=""),0, IF(AND(Tabela_33471[[#This Row],[Placar Mandante]]=Tabela_3[[#This Row],[Placar Mandante]],Tabela_33471[[#This Row],[Placar Visitante]]=Tabela_3[[#This Row],[Placar Visitante]]),3, IF(SIGN(Tabela_33471[[#This Row],[Placar Mandante]]-Tabela_33471[[#This Row],[Placar Visitante]])=SIGN(Tabela_3[[#This Row],[Placar Mandante]]-Tabela_3[[#This Row],[Placar Visitante]]),1,0))) -> 0
A12: 14.06. 20:00 | B12: 14/06/2026 | C12: 20:00 | D12: Costa do Marfim | E12: 0 | F12: x | G12: 1 | H12: Equador | I12: =IF(OR(Tabela_33471[[#This Row],[Placar Mandante]]="",Tabela_33471[[#This Row],[Placar Visitante]]="",Tabela_3[[#This Row],[Placar Mandante]]="",Tabela_3[[#This Row],[Placar Visitante]]=""),0, IF(AND(Tabela_33471[[#This Row],[Placar Mandante]]=Tabela_3[[#This Row],[Placar Mandante]],Tabela_33471[[#This Row],[Placar Visitante]]=Tabela_3[[#This Row],[Placar Visitante]]),3, IF(SIGN(Tabela_33471[[#This Row],[Placar Mandante]]-Tabela_33471[[#This Row],[Placar Visitante]])=SIGN(Tabela_3[[#This Row],[Placar Mandante]]-Tabela_3[[#This Row],[Placar Visitante]]),1,0))) -> 0
A13: 14.06. 23:00 | B13: 14/06/2026 | C13: 23:00 | D13: Suécia | E13: 1 | F13: x | G13: 0 | H13: Tunísia | I13: =IF(OR(Tabela_33471[[#This Row],[Placar Mandante]]="",Tabela_33471[[#This Row],[Placar Visitante]]="",Tabela_3[[#This Row],[Placar Mandante]]="",Tabela_3[[#This Row],[Placar Visitante]]=""),0, IF(AND(Tabela_33471[[#This Row],[Placar Mandante]]=Tabela_3[[#This Row],[Placar Mandante]],Tabela_33471[[#This Row],[Placar Visitante]]=Tabela_3[[#This Row],[Placar Visitante]]),3, IF(SIGN(Tabela_33471[[#This Row],[Placar Mandante]]-Tabela_33471[[#This Row],[Placar Visitante]])=SIGN(Tabela_3[[#This Row],[Placar Mandante]]-Tabela_3[[#This Row],[Placar Visitante]]),1,0))) -> 0
A14: 15.06. 13:00 | B14: 15/06/2026 | C14: 13:00 | D14: Espanha | E14: 1 | F14: x | G14: 0 | H14: Cabo Verde | I14: =IF(OR(Tabela_33471[[#This Row],[Placar Mandante]]="",Tabela_33471[[#This Row],[Placar Visitante]]="",Tabela_3[[#This Row],[Placar Mandante]]="",Tabela_3[[#This Row],[Placar Visitante]]=""),0, IF(AND(Tabela_33471[[#This Row],[Placar Mandante]]=Tabela_3[[#This Row],[Placar Mandante]],Tabela_33471[[#This Row],[Placar Visitante]]=Tabela_3[[#This Row],[Placar Visitante]]),3, IF(SIGN(Tabela_33471[[#This Row],[Placar Mandante]]-Tabela_33471[[#This Row],[Placar Visitante]])=SIGN(Tabela_3[[#This Row],[Placar Mandante]]-Tabela_3[[#This Row],[Placar Visitante]]),1,0))) -> 0
... A73: 27.06. 23:00 | B73: 27/06/2026 | C73: 23:00 | D73: Jordânia | E73: 0 | F73: x | G73: 1 | H73: Argentina | I73: =IF(OR(Tabela_33471[[#This Row],[Placar Mandante]]="",Tabela_33471[[#This Row],[Placar Visitante]]="",Tabela_3[[#This Row],[Placar Mandante]]="",Tabela_3[[#This Row],[Placar Visitante]]=""),0, IF(AND(Tabela_33471[[#This Row],[Placar Mandante]]=Tabela_3[[#This Row],[Placar Mandante]],Tabela_33471[[#This Row],[Placar Visitante]]=Tabela_3[[#This Row],[Placar Visitante]]),3, IF(SIGN(Tabela_33471[[#This Row],[Placar Mandante]]-Tabela_33471[[#This Row],[Placar Visitante]])=SIGN(Tabela_3[[#This Row],[Placar Mandante]]-Tabela_3[[#This Row],[Placar Visitante]]),1,0))) -> 0

Sheet Benjamin Cavallari
A1: Hora-Data | B1: Data | C1: Horário | D1: Mandante | E1: Placar Mandante | F1: x | G1: Placar Visitante | H1: Visitante | I1: Pontuação | K1: Pontuação
A2: 11.06. 16:00 | B2: 11/06/2026 | C2: 16:00 | D2: México | E2: 2 | F2: x | G2: 1 | H2: África do Sul | I2: =IF(OR(Tabela_3335[[#This Row],[Placar Mandante]]="",Tabela_3335[[#This Row],[Placar Visitante]]="",Tabela_3[[#This Row],[Placar Mandante]]="",Tabela_3[[#This Row],[Placar Visitante]]=""),0, IF(AND(Tabela_3335[[#This Row],[Placar Mandante]]=Tabela_3[[#This Row],[Placar Mandante]],Tabela_3335[[#This Row],[Placar Visitante]]=Tabela_3[[#This Row],[Placar Visitante]]),3, IF(SIGN(Tabela_3335[[#This Row],[Placar Mandante]]-Tabela_3335[[#This Row],[Placar Visitante]])=SIGN(Tabela_3[[#This Row],[Placar Mandante]]-Tabela_3[[#This Row],[Placar Visitante]]),1,0))) -> 0 | K2: =SUM(Tabela_3335[Pontuação]) -> 0
A3: 11.06. 23:00 | B3: 11/06/2026 | C3: 23:00 | D3: Coreia do Sul | E3: 1 | F3: x | G3: 0 | H3: Republica Tcheca | I3: =IF(OR(Tabela_3335[[#This Row],[Placar Mandante]]="",Tabela_3335[[#This Row],[Placar Visitante]]="",Tabela_3[[#This Row],[Placar Mandante]]="",Tabela_3[[#This Row],[Placar Visitante]]=""),0, IF(AND(Tabela_3335[[#This Row],[Placar Mandante]]=Tabela_3[[#This Row],[Placar Mandante]],Tabela_3335[[#This Row],[Placar Visitante]]=Tabela_3[[#This Row],[Placar Visitante]]),3, IF(SIGN(Tabela_3335[[#This Row],[Placar Mandante]]-Tabela_3335[[#This Row],[Placar Visitante]])=SIGN(Tabela_3[[#This Row],[Placar Mandante]]-Tabela_3[[#This Row],[Placar Visitante]]),1,0))) -> 0
A4: 12.06. 16:00 | B4: 12/06/2026 | C4: 16:00 | D4: Canadá | E4: 1 | F4: x | G4: 1 | H4: Bósnia e Herzegovina | I4: =IF(OR(Tabela_3335[[#This Row],[Placar Mandante]]="",Tabela_3335[[#This Row],[Placar Visitante]]="",Tabela_3[[#This Row],[Placar Mandante]]="",Tabela_3[[#This Row],[Placar Visitante]]=""),0, IF(AND(Tabela_3335[[#This Row],[Placar Mandante]]=Tabela_3[[#This Row],[Placar Mandante]],Tabela_3335[[#This Row],[Placar Visitante]]=Tabela_3[[#This Row],[Placar Visitante]]),3, IF(SIGN(Tabela_3335[[#This Row],[Placar Mandante]]-Tabela_3335[[#This Row],[Placar Visitante]])=SIGN(Tabela_3[[#This Row],[Placar Mandante]]-Tabela_3[[#This Row],[Placar Visitante]]),1,0))) -> 0
A5: 12.06. 22:00 | B5: 12/06/2026 | C5: 22:00 | D5: EUA | E5: 1 | F5: x | G5: 1 | H5: Paraguai | I5: =IF(OR(Tabela_3335[[#This Row],[Placar Mandante]]="",Tabela_3335[[#This Row],[Placar Visitante]]="",Tabela_3[[#This Row],[Placar Mandante]]="",Tabela_3[[#This Row],[Placar Visitante]]=""),0, IF(AND(Tabela_3335[[#This Row],[Placar Mandante]]=Tabela_3[[#This Row],[Placar Mandante]],Tabela_3335[[#This Row],[Placar Visitante]]=Tabela_3[[#This Row],[Placar Visitante]]),3, IF(SIGN(Tabela_3335[[#This Row],[Placar Mandante]]-Tabela_3335[[#This Row],[Placar Visitante]])=SIGN(Tabela_3[[#This Row],[Placar Mandante]]-Tabela_3[[#This Row],[Placar Visitante]]),1,0))) -> 0
A6: 13.06. 16:00 | B6: 13/06/2026 | C6: 16:00 | D6: Catar | E6: 0 | F6: x | G6: 1 | H6: Suíça | I6: =IF(OR(Tabela_3335[[#This Row],[Placar Mandante]]="",Tabela_3335[[#This Row],[Placar Visitante]]="",Tabela_3[[#This Row],[Placar Mandante]]="",Tabela_3[[#This Row],[Placar Visitante]]=""),0, IF(AND(Tabela_3335[[#This Row],[Placar Mandante]]=Tabela_3[[#This Row],[Placar Mandante]],Tabela_3335[[#This Row],[Placar Visitante]]=Tabela_3[[#This Row],[Placar Visitante]]),3, IF(SIGN(Tabela_3335[[#This Row],[Placar Mandante]]-Tabela_3335[[#This Row],[Placar Visitante]])=SIGN(Tabela_3[[#This Row],[Placar Mandante]]-Tabela_3[[#This Row],[Placar Visitante]]),1,0))) -> 0
A7: 13.06. 19:00 | B7: 13/06/2026 | C7: 19:00 | D7: Brasil | E7: 2 | F7: x | G7: 1 | H7: Marrocos | I7: =IF(OR(Tabela_3335[[#This Row],[Placar Mandante]]="",Tabela_3335[[#This Row],[Placar Visitante]]="",Tabela_3[[#This Row],[Placar Mandante]]="",Tabela_3[[#This Row],[Placar Visitante]]=""),0, IF(AND(Tabela_3335[[#This Row],[Placar Mandante]]=Tabela_3[[#This Row],[Placar Mandante]],Tabela_3335[[#This Row],[Placar Visitante]]=Tabela_3[[#This Row],[Placar Visitante]]),3, IF(SIGN(Tabela_3335[[#This Row],[Placar Mandante]]-Tabela_3335[[#This Row],[Placar Visitante]])=SIGN(Tabela_3[[#This Row],[Placar Mandante]]-Tabela_3[[#This Row],[Placar Visitante]]),1,0))) -> 0
A8: 13.06. 22:00 | B8: 13/06/2026 | C8: 22:00 | D8: Haiti | E8: 0 | F8: x | G8: 2 | H8: Escócia | I8: =IF(OR(Tabela_3335[[#This Row],[Placar Mandante]]="",Tabela_3335[[#This Row],[Placar Visitante]]="",Tabela_3[[#This Row],[Placar Mandante]]="",Tabela_3[[#This Row],[Placar Visitante]]=""),0, IF(AND(Tabela_3335[[#This Row],[Placar Mandante]]=Tabela_3[[#This Row],[Placar Mandante]],Tabela_3335[[#This Row],[Placar Visitante]]=Tabela_3[[#This Row],[Placar Visitante]]),3, IF(SIGN(Tabela_3335[[#This Row],[Placar Mandante]]-Tabela_3335[[#This Row],[Placar Visitante]])=SIGN(Tabela_3[[#This Row],[Placar Mandante]]-Tabela_3[[#This Row],[Placar Visitante]]),1,0))) -> 0
A9: 14.06. 01:00 | B9: 14/06/2026 | C9: 01:00 | D9: Austrália | E9: 1 | F9: x | G9: 1 | H9: Turquia | I9: =IF(OR(Tabela_3335[[#This Row],[Placar Mandante]]="",Tabela_3335[[#This Row],[Placar Visitante]]="",Tabela_3[[#This Row],[Placar Mandante]]="",Tabela_3[[#This Row],[Placar Visitante]]=""),0, IF(AND(Tabela_3335[[#This Row],[Placar Mandante]]=Tabela_3[[#This Row],[Placar Mandante]],Tabela_3335[[#This Row],[Placar Visitante]]=Tabela_3[[#This Row],[Placar Visitante]]),3, IF(SIGN(Tabela_3335[[#This Row],[Placar Mandante]]-Tabela_3335[[#This Row],[Placar Visitante]])=SIGN(Tabela_3[[#This Row],[Placar Mandante]]-Tabela_3[[#This Row],[Placar Visitante]]),1,0))) -> 0
A10: 14.06. 14:00 | B10: 14/06/2026 | C10: 14:00 | D10: Alemanha | E10: 3 | F10: x | G10: 0 | H10: Curaçau | I10: =IF(OR(Tabela_3335[[#This Row],[Placar Mandante]]="",Tabela_3335[[#This Row],[Placar Visitante]]="",Tabela_3[[#This Row],[Placar Mandante]]="",Tabela_3[[#This Row],[Placar Visitante]]=""),0, IF(AND(Tabela_3335[[#This Row],[Placar Mandante]]=Tabela_3[[#This Row],[Placar Mandante]],Tabela_3335[[#This Row],[Placar Visitante]]=Tabela_3[[#This Row],[Placar Visitante]]),3, IF(SIGN(Tabela_3335[[#This Row],[Placar Mandante]]-Tabela_3335[[#This Row],[Placar Visitante]])=SIGN(Tabela_3[[#This Row],[Placar Mandante]]-Tabela_3[[#This Row],[Placar Visitante]]),1,0))) -> 0
A11: 14.06. 17:00 | B11: 14/06/2026 | C11: 17:00 | D11: Países Baixos | E11: 2 | F11: x | G11: 2 | H11: Japão | I11: =IF(OR(Tabela_3335[[#This Row],[Placar Mandante]]="",Tabela_3335[[#This Row],[Placar Visitante]]="",Tabela_3[[#This Row],[Placar Mandante]]="",Tabela_3[[#This Row],[Placar Visitante]]=""),0, IF(AND(Tabela_3335[[#This Row],[Placar Mandante]]=Tabela_3[[#This Row],[Placar Mandante]],Tabela_3335[[#This Row],[Placar Visitante]]=Tabela_3[[#This Row],[Placar Visitante]]),3, IF(SIGN(Tabela_3335[[#This Row],[Placar Mandante]]-Tabela_3335[[#This Row],[Placar Visitante]])=SIGN(Tabela_3[[#This Row],[Placar Mandante]]-Tabela_3[[#This Row],[Placar Visitante]]),1,0))) -> 0
A12: 14.06. 20:00 | B12: 14/06/2026 | C12: 20:00 | D12: Costa do Marfim | E12: 1 | F12: x | G12: 1 | H12: Equador | I12: =IF(OR(Tabela_3335[[#This Row],[Placar Mandante]]="",Tabela_3335[[#This Row],[Placar Visitante]]="",Tabela_3[[#This Row],[Placar Mandante]]="",Tabela_3[[#This Row],[Placar Visitante]]=""),0, IF(AND(Tabela_3335[[#This Row],[Placar Mandante]]=Tabela_3[[#This Row],[Placar Mandante]],Tabela_3335[[#This Row],[Placar Visitante]]=Tabela_3[[#This Row],[Placar Visitante]]),3, IF(SIGN(Tabela_3335[[#This Row],[Placar Mandante]]-Tabela_3335[[#This Row],[Placar Visitante]])=SIGN(Tabela_3[[#This Row],[Placar Mandante]]-Tabela_3[[#This Row],[Placar Visitante]]),1,0))) -> 0
A13: 14.06. 23:00 | B13: 14/06/2026 | C13: 23:00 | D13: Suécia | E13: 1 | F13: x | G13: 2 | H13: Tunísia | I13: =IF(OR(Tabela_3335[[#This Row],[Placar Mandante]]="",Tabela_3335[[#This Row],[Placar Visitante]]="",Tabela_3[[#This Row],[Placar Mandante]]="",Tabela_3[[#This Row],[Placar Visitante]]=""),0, IF(AND(Tabela_3335[[#This Row],[Placar Mandante]]=Tabela_3[[#This Row],[Placar Mandante]],Tabela_3335[[#This Row],[Placar Visitante]]=Tabela_3[[#This Row],[Placar Visitante]]),3, IF(SIGN(Tabela_3335[[#This Row],[Placar Mandante]]-Tabela_3335[[#This Row],[Placar Visitante]])=SIGN(Tabela_3[[#This Row],[Placar Mandante]]-Tabela_3[[#This Row],[Placar Visitante]]),1,0))) -> 0
A14: 15.06. 13:00 | B14: 15/06/2026 | C14: 13:00 | D14: Espanha | E14: 3 | F14: x | G14: 0 | H14: Cabo Verde | I14: =IF(OR(Tabela_3335[[#This Row],[Placar Mandante]]="",Tabela_3335[[#This Row],[Placar Visitante]]="",Tabela_3[[#This Row],[Placar Mandante]]="",Tabela_3[[#This Row],[Placar Visitante]]=""),0, IF(AND(Tabela_3335[[#This Row],[Placar Mandante]]=Tabela_3[[#This Row],[Placar Mandante]],Tabela_3335[[#This Row],[Placar Visitante]]=Tabela_3[[#This Row],[Placar Visitante]]),3, IF(SIGN(Tabela_3335[[#This Row],[Placar Mandante]]-Tabela_3335[[#This Row],[Placar Visitante]])=SIGN(Tabela_3[[#This Row],[Placar Mandante]]-Tabela_3[[#This Row],[Placar Visitante]]),1,0))) -> 0
... A73: 27.06. 23:00 | B73: 27/06/2026 | C73: 23:00 | D73: Jordânia | E73: 0 | F73: x | G73: 3 | H73: Argentina | I73: =IF(OR(Tabela_3335[[#This Row],[Placar Mandante]]="",Tabela_3335[[#This Row],[Placar Visitante]]="",Tabela_3[[#This Row],[Placar Mandante]]="",Tabela_3[[#This Row],[Placar Visitante]]=""),0, IF(AND(Tabela_3335[[#This Row],[Placar Mandante]]=Tabela_3[[#This Row],[Placar Mandante]],Tabela_3335[[#This Row],[Placar Visitante]]=Tabela_3[[#This Row],[Placar Visitante]]),3, IF(SIGN(Tabela_3335[[#This Row],[Placar Mandante]]-Tabela_3335[[#This Row],[Placar Visitante]])=SIGN(Tabela_3[[#This Row],[Placar Mandante]]-Tabela_3[[#This Row],[Placar Visitante]]),1,0))) -> 0

Sheet Breno
A1: Hora-Data | B1: Data | C1: Horário | D1: Mandante | E1: Placar Mandante | F1: x | G1: Placar Visitante | H1: Visitante | I1: Pontuação | K1: Pontuação
A2: 11.06. 16:00 | B2: 11/06/2026 | C2: 16:00 | D2: México | E2: 2 | F2: x | G2: 0 | H2: África do Sul | I2: =IF(OR(Tabela_33472[[#This Row],[Placar Mandante]]="",Tabela_33472[[#This Row],[Placar Visitante]]="",Tabela_3[[#This Row],[Placar Mandante]]="",Tabela_3[[#This Row],[Placar Visitante]]=""),0, IF(AND(Tabela_33472[[#This Row],[Placar Mandante]]=Tabela_3[[#This Row],[Placar Mandante]],Tabela_33472[[#This Row],[Placar Visitante]]=Tabela_3[[#This Row],[Placar Visitante]]),3, IF(SIGN(Tabela_33472[[#This Row],[Placar Mandante]]-Tabela_33472[[#This Row],[Placar Visitante]])=SIGN(Tabela_3[[#This Row],[Placar Mandante]]-Tabela_3[[#This Row],[Placar Visitante]]),1,0))) -> 0 | K2: =SUM(Tabela_33472[Pontuação]) -> 0
A3: 11.06. 23:00 | B3: 11/06/2026 | C3: 23:00 | D3: Coreia do Sul | E3: 1 | F3: x | G3: 2 | H3: Republica Tcheca | I3: =IF(OR(Tabela_33472[[#This Row],[Placar Mandante]]="",Tabela_33472[[#This Row],[Placar Visitante]]="",Tabela_3[[#This Row],[Placar Mandante]]="",Tabela_3[[#This Row],[Placar Visitante]]=""),0, IF(AND(Tabela_33472[[#This Row],[Placar Mandante]]=Tabela_3[[#This Row],[Placar Mandante]],Tabela_33472[[#This Row],[Placar Visitante]]=Tabela_3[[#This Row],[Placar Visitante]]),3, IF(SIGN(Tabela_33472[[#This Row],[Placar Mandante]]-Tabela_33472[[#This Row],[Placar Visitante]])=SIGN(Tabela_3[[#This Row],[Placar Mandante]]-Tabela_3[[#This Row],[Placar Visitante]]),1,0))) -> 0
A4: 12.06. 16:00 | B4: 12/06/2026 | C4: 16:00 | D4: Canadá | E4: 1 | F4: x | G4: 0 | H4: Bósnia e Herzegovina | I4: =IF(OR(Tabela_33472[[#This Row],[Placar Mandante]]="",Tabela_33472[[#This Row],[Placar Visitante]]="",Tabela_3[[#This Row],[Placar Mandante]]="",Tabela_3[[#This Row],[Placar Visitante]]=""),0, IF(AND(Tabela_33472[[#This Row],[Placar Mandante]]=Tabela_3[[#This Row],[Placar Mandante]],Tabela_33472[[#This Row],[Placar Visitante]]=Tabela_3[[#This Row],[Placar Visitante]]),3, IF(SIGN(Tabela_33472[[#This Row],[Placar Mandante]]-Tabela_33472[[#This Row],[Placar Visitante]])=SIGN(Tabela_3[[#This Row],[Placar Mandante]]-Tabela_3[[#This Row],[Placar Visitante]]),1,0))) -> 0
A5: 12.06. 22:00 | B5: 12/06/2026 | C5: 22:00 | D5: EUA | E5: 2 | F5: x | G5: 1 | H5: Paraguai | I5: =IF(OR(Tabela_33472[[#This Row],[Placar Mandante]]="",Tabela_33472[[#This Row],[Placar Visitante]]="",Tabela_3[[#This Row],[Placar Mandante]]="",Tabela_3[[#This Row],[Placar Visitante]]=""),0, IF(AND(Tabela_33472[[#This Row],[Placar Mandante]]=Tabela_3[[#This Row],[Placar Mandante]],Tabela_33472[[#This Row],[Placar Visitante]]=Tabela_3[[#This Row],[Placar Visitante]]),3, IF(SIGN(Tabela_33472[[#This Row],[Placar Mandante]]-Tabela_33472[[#This Row],[Placar Visitante]])=SIGN(Tabela_3[[#This Row],[Placar Mandante]]-Tabela_3[[#This Row],[Placar Visitante]]),1,0))) -> 0
A6: 13.06. 16:00 | B6: 13/06/2026 | C6: 16:00 | D6: Catar | E6: 0 | F6: x | G6: 2 | H6: Suíça | I6: =IF(OR(Tabela_33472[[#This Row],[Placar Mandante]]="",Tabela_33472[[#This Row],[Placar Visitante]]="",Tabela_3[[#This Row],[Placar Mandante]]="",Tabela_3[[#This Row],[Placar Visitante]]=""),0, IF(AND(Tabela_33472[[#This Row],[Placar Mandante]]=Tabela_3[[#This Row],[Placar Mandante]],Tabela_33472[[#This Row],[Placar Visitante]]=Tabela_3[[#This Row],[Placar Visitante]]),3, IF(SIGN(Tabela_33472[[#This Row],[Placar Mandante]]-Tabela_33472[[#This Row],[Placar Visitante]])=SIGN(Tabela_3[[#This Row],[Placar Mandante]]-Tabela_3[[#This Row],[Placar Visitante]]),1,0))) -> 0
A7: 13.06. 19:00 | B7: 13/06/2026 | C7: 19:00 | D7: Brasil | E7: 2 | F7: x | G7: 1 | H7: Marrocos | I7: =IF(OR(Tabela_33472[[#This Row],[Placar Mandante]]="",Tabela_33472[[#This Row],[Placar Visitante]]="",Tabela_3[[#This Row],[Placar Mandante]]="",Tabela_3[[#This Row],[Placar Visitante]]=""),0, IF(AND(Tabela_33472[[#This Row],[Placar Mandante]]=Tabela_3[[#This Row],[Placar Mandante]],Tabela_33472[[#This Row],[Placar Visitante]]=Tabela_3[[#This Row],[Placar Visitante]]),3, IF(SIGN(Tabela_33472[[#This Row],[Placar Mandante]]-Tabela_33472[[#This Row],[Placar Visitante]])=SIGN(Tabela_3[[#This Row],[Placar Mandante]]-Tabela_3[[#This Row],[Placar Visitante]]),1,0))) -> 0
A8: 13.06. 22:00 | B8: 13/06/2026 | C8: 22:00 | D8: Haiti | E8: 0 | F8: x | G8: 2 | H8: Escócia | I8: =IF(OR(Tabela_33472[[#This Row],[Placar Mandante]]="",Tabela_33472[[#This Row],[Placar Visitante]]="",Tabela_3[[#This Row],[Placar Mandante]]="",Tabela_3[[#This Row],[Placar Visitante]]=""),0, IF(AND(Tabela_33472[[#This Row],[Placar Mandante]]=Tabela_3[[#This Row],[Placar Mandante]],Tabela_33472[[#This Row],[Placar Visitante]]=Tabela_3[[#This Row],[Placar Visitante]]),3, IF(SIGN(Tabela_33472[[#This Row],[Placar Mandante]]-Tabela_33472[[#This Row],[Placar Visitante]])=SIGN(Tabela_3[[#This Row],[Placar Mandante]]-Tabela_3[[#This Row],[Placar Visitante]]),1,0))) -> 0
A9: 14.06. 01:00 | B9: 14/06/2026 | C9: 01:00 | D9: Austrália | E9: 1 | F9: x | G9: 2 | H9: Turquia | I9: =IF(OR(Tabela_33472[[#This Row],[Placar Mandante]]="",Tabela_33472[[#This Row],[Placar Visitante]]="",Tabela_3[[#This Row],[Placar Mandante]]="",Tabela_3[[#This Row],[Placar Visitante]]=""),0, IF(AND(Tabela_33472[[#This Row],[Placar Mandante]]=Tabela_3[[#This Row],[Placar Mandante]],Tabela_33472[[#This Row],[Placar Visitante]]=Tabela_3[[#This Row],[Placar Visitante]]),3, IF(SIGN(Tabela_33472[[#This Row],[Placar Mandante]]-Tabela_33472[[#This Row],[Placar Visitante]])=SIGN(Tabela_3[[#This Row],[Placar Mandante]]-Tabela_3[[#This Row],[Placar Visitante]]),1,0))) -> 0
A10: 14.06. 14:00 | B10: 14/06/2026 | C10: 14:00 | D10: Alemanha | E10: 4 | F10: x | G10: 0 | H10: Curaçau | I10: =IF(OR(Tabela_33472[[#This Row],[Placar Mandante]]="",Tabela_33472[[#This Row],[Placar Visitante]]="",Tabela_3[[#This Row],[Placar Mandante]]="",Tabela_3[[#This Row],[Placar Visitante]]=""),0, IF(AND(Tabela_33472[[#This Row],[Placar Mandante]]=Tabela_3[[#This Row],[Placar Mandante]],Tabela_33472[[#This Row],[Placar Visitante]]=Tabela_3[[#This Row],[Placar Visitante]]),3, IF(SIGN(Tabela_33472[[#This Row],[Placar Mandante]]-Tabela_33472[[#This Row],[Placar Visitante]])=SIGN(Tabela_3[[#This Row],[Placar Mandante]]-Tabela_3[[#This Row],[Placar Visitante]]),1,0))) -> 0
A11: 14.06. 17:00 | B11: 14/06/2026 | C11: 17:00 | D11: Países Baixos | E11: 2 | F11: x | G11: 2 | H11: Japão | I11: =IF(OR(Tabela_33472[[#This Row],[Placar Mandante]]="",Tabela_33472[[#This Row],[Placar Visitante]]="",Tabela_3[[#This Row],[Placar Mandante]]="",Tabela_3[[#This Row],[Placar Visitante]]=""),0, IF(AND(Tabela_33472[[#This Row],[Placar Mandante]]=Tabela_3[[#This Row],[Placar Mandante]],Tabela_33472[[#This Row],[Placar Visitante]]=Tabela_3[[#This Row],[Placar Visitante]]),3, IF(SIGN(Tabela_33472[[#This Row],[Placar Mandante]]-Tabela_33472[[#This Row],[Placar Visitante]])=SIGN(Tabela_3[[#This Row],[Placar Mandante]]-Tabela_3[[#This Row],[Placar Visitante]]),1,0))) -> 0
A12: 14.06. 20:00 | B12: 14/06/2026 | C12: 20:00 | D12: Costa do Marfim | E12: 1 | F12: x | G12: 1 | H12: Equador | I12: =IF(OR(Tabela_33472[[#This Row],[Placar Mandante]]="",Tabela_33472[[#This Row],[Placar Visitante]]="",Tabela_3[[#This Row],[Placar Mandante]]="",Tabela_3[[#This Row],[Placar Visitante]]=""),0, IF(AND(Tabela_33472[[#This Row],[Placar Mandante]]=Tabela_3[[#This Row],[Placar Mandante]],Tabela_33472[[#This Row],[Placar Visitante]]=Tabela_3[[#This Row],[Placar Visitante]]),3, IF(SIGN(Tabela_33472[[#This Row],[Placar Mandante]]-Tabela_33472[[#This Row],[Placar Visitante]])=SIGN(Tabela_3[[#This Row],[Placar Mandante]]-Tabela_3[[#This Row],[Placar Visitante]]),1,0))) -> 0
